[2024-08-19T06:17:01.408+0000] {local_task_job_runner.py:120} INFO - ::group::Pre task execution logs
[2024-08-19T06:17:01.419+0000] {taskinstance.py:2076} INFO - Dependencies all met for dep_context=non-requeueable deps ti=<TaskInstance: predict_values_TS_38.get_deaths_dataset.save_data_to_s3 scheduled__2024-08-11T00:00:00+00:00 [queued]>
[2024-08-19T06:17:01.423+0000] {taskinstance.py:2076} INFO - Dependencies all met for dep_context=requeueable deps ti=<TaskInstance: predict_values_TS_38.get_deaths_dataset.save_data_to_s3 scheduled__2024-08-11T00:00:00+00:00 [queued]>
[2024-08-19T06:17:01.424+0000] {taskinstance.py:2306} INFO - Starting attempt 1 of 2
[2024-08-19T06:17:01.434+0000] {taskinstance.py:2330} INFO - Executing <Task(PythonOperator): get_deaths_dataset.save_data_to_s3> on 2024-08-11 00:00:00+00:00
[2024-08-19T06:17:01.444+0000] {warnings.py:110} WARNING - /home/airflow/.local/lib/python3.12/site-packages/airflow/task/task_runner/standard_task_runner.py:61: DeprecationWarning: This process (pid=630) is multi-threaded, use of fork() may lead to deadlocks in the child.
  pid = os.fork()

[2024-08-19T06:17:01.445+0000] {standard_task_runner.py:63} INFO - Started process 679 to run task
[2024-08-19T06:17:01.445+0000] {standard_task_runner.py:90} INFO - Running: ['airflow', 'tasks', 'run', 'predict_values_TS_38', 'get_deaths_dataset.save_data_to_s3', 'scheduled__2024-08-11T00:00:00+00:00', '--job-id', '256', '--raw', '--subdir', 'DAGS_FOLDER/etl.py', '--cfg-path', '/tmp/tmp2fjwb3d6']
[2024-08-19T06:17:01.447+0000] {standard_task_runner.py:91} INFO - Job 256: Subtask get_deaths_dataset.save_data_to_s3
[2024-08-19T06:17:01.478+0000] {task_command.py:426} INFO - Running <TaskInstance: predict_values_TS_38.get_deaths_dataset.save_data_to_s3 scheduled__2024-08-11T00:00:00+00:00 [running]> on host 66f3029c143d
[2024-08-19T06:17:01.533+0000] {taskinstance.py:2648} INFO - Exporting env vars: AIRFLOW_CTX_DAG_OWNER='Ruslan Solarev' AIRFLOW_CTX_DAG_ID='predict_values_TS_38' AIRFLOW_CTX_TASK_ID='get_deaths_dataset.save_data_to_s3' AIRFLOW_CTX_EXECUTION_DATE='2024-08-11T00:00:00+00:00' AIRFLOW_CTX_TRY_NUMBER='1' AIRFLOW_CTX_DAG_RUN_ID='scheduled__2024-08-11T00:00:00+00:00'
[2024-08-19T06:17:01.534+0000] {taskinstance.py:430} INFO - ::endgroup::
[2024-08-19T06:17:01.548+0000] {base.py:84} INFO - Using connection ID 'minio_conn' for task execution.
[2024-08-19T06:17:01.549+0000] {connection_wrapper.py:387} INFO - AWS Connection (conn_id='minio_conn', conn_type='aws') credentials retrieved from extra.
[2024-08-19T06:17:01.549+0000] {warnings.py:110} WARNING - <string>:9: AirflowProviderDeprecationWarning: extra['host'] is deprecated and will be removed in a future release. Please set extra['endpoint_url'] instead

[2024-08-19T06:17:05.968+0000] {logging_mixin.py:188} WARNING - --- Logging error ---
[2024-08-19T06:17:05.971+0000] {logging_mixin.py:188} WARNING - Traceback (most recent call last):
[2024-08-19T06:17:05.972+0000] {logging_mixin.py:188} WARNING -   File "/home/airflow/.local/lib/python3.12/site-packages/urllib3/connectionpool.py", line 793, in urlopen
    response = self._make_request(
               ^^^^^^^^^^^^^^^^^^^
[2024-08-19T06:17:05.972+0000] {logging_mixin.py:188} WARNING -   File "/home/airflow/.local/lib/python3.12/site-packages/urllib3/connectionpool.py", line 537, in _make_request
    response = conn.getresponse()
               ^^^^^^^^^^^^^^^^^^
[2024-08-19T06:17:05.972+0000] {logging_mixin.py:188} WARNING -   File "/home/airflow/.local/lib/python3.12/site-packages/urllib3/connection.py", line 466, in getresponse
    httplib_response = super().getresponse()
                       ^^^^^^^^^^^^^^^^^^^^^
[2024-08-19T06:17:05.973+0000] {logging_mixin.py:188} WARNING -   File "/usr/local/lib/python3.12/http/client.py", line 1428, in getresponse
    response.begin()
[2024-08-19T06:17:05.973+0000] {logging_mixin.py:188} WARNING -   File "/usr/local/lib/python3.12/http/client.py", line 331, in begin
    version, status, reason = self._read_status()
                              ^^^^^^^^^^^^^^^^^^^
[2024-08-19T06:17:05.973+0000] {logging_mixin.py:188} WARNING -   File "/usr/local/lib/python3.12/http/client.py", line 313, in _read_status
    raise BadStatusLine(line)
[2024-08-19T06:17:05.973+0000] {logging_mixin.py:188} WARNING - http.client.BadStatusLine: Accept-Encoding: identity
[2024-08-19T06:17:05.974+0000] {logging_mixin.py:188} WARNING - 
During handling of the above exception, another exception occurred:
[2024-08-19T06:17:05.974+0000] {logging_mixin.py:188} WARNING - Traceback (most recent call last):
[2024-08-19T06:17:05.974+0000] {logging_mixin.py:188} WARNING -   File "/home/airflow/.local/lib/python3.12/site-packages/botocore/httpsession.py", line 464, in send
    urllib_response = conn.urlopen(
                      ^^^^^^^^^^^^^
[2024-08-19T06:17:05.975+0000] {logging_mixin.py:188} WARNING -   File "/home/airflow/.local/lib/python3.12/site-packages/urllib3/connectionpool.py", line 847, in urlopen
    retries = retries.increment(
              ^^^^^^^^^^^^^^^^^^
[2024-08-19T06:17:05.975+0000] {logging_mixin.py:188} WARNING -   File "/home/airflow/.local/lib/python3.12/site-packages/urllib3/util/retry.py", line 445, in increment
    raise reraise(type(error), error, _stacktrace)
          ^^^^^^^^^^^^^^^^^^^^^^^^^^^^^^^^^^^^^^^^
[2024-08-19T06:17:05.975+0000] {logging_mixin.py:188} WARNING -   File "/home/airflow/.local/lib/python3.12/site-packages/urllib3/util/util.py", line 38, in reraise
    raise value.with_traceback(tb)
[2024-08-19T06:17:05.975+0000] {logging_mixin.py:188} WARNING -   File "/home/airflow/.local/lib/python3.12/site-packages/urllib3/connectionpool.py", line 793, in urlopen
    response = self._make_request(
               ^^^^^^^^^^^^^^^^^^^
[2024-08-19T06:17:05.976+0000] {logging_mixin.py:188} WARNING -   File "/home/airflow/.local/lib/python3.12/site-packages/urllib3/connectionpool.py", line 537, in _make_request
    response = conn.getresponse()
               ^^^^^^^^^^^^^^^^^^
[2024-08-19T06:17:05.976+0000] {logging_mixin.py:188} WARNING -   File "/home/airflow/.local/lib/python3.12/site-packages/urllib3/connection.py", line 466, in getresponse
    httplib_response = super().getresponse()
                       ^^^^^^^^^^^^^^^^^^^^^
[2024-08-19T06:17:05.976+0000] {logging_mixin.py:188} WARNING -   File "/usr/local/lib/python3.12/http/client.py", line 1428, in getresponse
    response.begin()
[2024-08-19T06:17:05.976+0000] {logging_mixin.py:188} WARNING -   File "/usr/local/lib/python3.12/http/client.py", line 331, in begin
    version, status, reason = self._read_status()
                              ^^^^^^^^^^^^^^^^^^^
[2024-08-19T06:17:05.977+0000] {logging_mixin.py:188} WARNING -   File "/usr/local/lib/python3.12/http/client.py", line 313, in _read_status
    raise BadStatusLine(line)
[2024-08-19T06:17:05.977+0000] {logging_mixin.py:188} WARNING - urllib3.exceptions.ProtocolError: ('Connection aborted.', BadStatusLine('Accept-Encoding: identity\r\n'))
[2024-08-19T06:17:05.977+0000] {logging_mixin.py:188} WARNING - 
During handling of the above exception, another exception occurred:
[2024-08-19T06:17:05.977+0000] {logging_mixin.py:188} WARNING - Traceback (most recent call last):
[2024-08-19T06:17:05.978+0000] {logging_mixin.py:188} WARNING -   File "/opt/airflow/dags/tasks/save_data_to_s3.py", line 10, in save_data_to_s3
    hook.load_file(
[2024-08-19T06:17:05.978+0000] {logging_mixin.py:188} WARNING -   File "/home/airflow/.local/lib/python3.12/site-packages/airflow/providers/amazon/aws/hooks/s3.py", line 135, in wrapper
    return func(*bound_args.args, **bound_args.kwargs)
           ^^^^^^^^^^^^^^^^^^^^^^^^^^^^^^^^^^^^^^^^^^^
[2024-08-19T06:17:05.979+0000] {logging_mixin.py:188} WARNING -   File "/home/airflow/.local/lib/python3.12/site-packages/airflow/providers/amazon/aws/hooks/s3.py", line 89, in wrapper
    return func(*bound_args.args, **bound_args.kwargs)
           ^^^^^^^^^^^^^^^^^^^^^^^^^^^^^^^^^^^^^^^^^^^
[2024-08-19T06:17:05.979+0000] {logging_mixin.py:188} WARNING -   File "/home/airflow/.local/lib/python3.12/site-packages/airflow/providers/amazon/aws/hooks/s3.py", line 1098, in load_file
    client.upload_file(filename, bucket_name, key, ExtraArgs=extra_args, Config=self.transfer_config)
[2024-08-19T06:17:05.979+0000] {logging_mixin.py:188} WARNING -   File "/home/airflow/.local/lib/python3.12/site-packages/boto3/s3/inject.py", line 145, in upload_file
    return transfer.upload_file(
           ^^^^^^^^^^^^^^^^^^^^^
[2024-08-19T06:17:05.980+0000] {logging_mixin.py:188} WARNING -   File "/home/airflow/.local/lib/python3.12/site-packages/boto3/s3/transfer.py", line 371, in upload_file
    future.result()
[2024-08-19T06:17:05.980+0000] {logging_mixin.py:188} WARNING -   File "/home/airflow/.local/lib/python3.12/site-packages/s3transfer/futures.py", line 103, in result
    return self._coordinator.result()
           ^^^^^^^^^^^^^^^^^^^^^^^^^^
[2024-08-19T06:17:05.980+0000] {logging_mixin.py:188} WARNING -   File "/home/airflow/.local/lib/python3.12/site-packages/s3transfer/futures.py", line 266, in result
    raise self._exception
[2024-08-19T06:17:05.981+0000] {logging_mixin.py:188} WARNING -   File "/home/airflow/.local/lib/python3.12/site-packages/s3transfer/tasks.py", line 139, in __call__
    return self._execute_main(kwargs)
           ^^^^^^^^^^^^^^^^^^^^^^^^^^
[2024-08-19T06:17:05.981+0000] {logging_mixin.py:188} WARNING -   File "/home/airflow/.local/lib/python3.12/site-packages/s3transfer/tasks.py", line 162, in _execute_main
    return_value = self._main(**kwargs)
                   ^^^^^^^^^^^^^^^^^^^^
[2024-08-19T06:17:05.981+0000] {logging_mixin.py:188} WARNING -   File "/home/airflow/.local/lib/python3.12/site-packages/s3transfer/upload.py", line 764, in _main
    client.put_object(Bucket=bucket, Key=key, Body=body, **extra_args)
[2024-08-19T06:17:05.982+0000] {logging_mixin.py:188} WARNING -   File "/home/airflow/.local/lib/python3.12/site-packages/botocore/client.py", line 553, in _api_call
    return self._make_api_call(operation_name, kwargs)
           ^^^^^^^^^^^^^^^^^^^^^^^^^^^^^^^^^^^^^^^^^^^
[2024-08-19T06:17:05.982+0000] {logging_mixin.py:188} WARNING -   File "/home/airflow/.local/lib/python3.12/site-packages/botocore/client.py", line 989, in _make_api_call
    http, parsed_response = self._make_request(
                            ^^^^^^^^^^^^^^^^^^^
[2024-08-19T06:17:05.982+0000] {logging_mixin.py:188} WARNING -   File "/home/airflow/.local/lib/python3.12/site-packages/botocore/client.py", line 1015, in _make_request
    return self._endpoint.make_request(operation_model, request_dict)
           ^^^^^^^^^^^^^^^^^^^^^^^^^^^^^^^^^^^^^^^^^^^^^^^^^^^^^^^^^^
[2024-08-19T06:17:05.982+0000] {logging_mixin.py:188} WARNING -   File "/home/airflow/.local/lib/python3.12/site-packages/botocore/endpoint.py", line 119, in make_request
    return self._send_request(request_dict, operation_model)
           ^^^^^^^^^^^^^^^^^^^^^^^^^^^^^^^^^^^^^^^^^^^^^^^^^
[2024-08-19T06:17:05.982+0000] {logging_mixin.py:188} WARNING -   File "/home/airflow/.local/lib/python3.12/site-packages/botocore/endpoint.py", line 202, in _send_request
    while self._needs_retry(
          ^^^^^^^^^^^^^^^^^^
[2024-08-19T06:17:05.983+0000] {logging_mixin.py:188} WARNING -   File "/home/airflow/.local/lib/python3.12/site-packages/botocore/endpoint.py", line 354, in _needs_retry
    responses = self._event_emitter.emit(
                ^^^^^^^^^^^^^^^^^^^^^^^^^
[2024-08-19T06:17:05.983+0000] {logging_mixin.py:188} WARNING -   File "/home/airflow/.local/lib/python3.12/site-packages/botocore/hooks.py", line 412, in emit
    return self._emitter.emit(aliased_event_name, **kwargs)
           ^^^^^^^^^^^^^^^^^^^^^^^^^^^^^^^^^^^^^^^^^^^^^^^^
[2024-08-19T06:17:05.983+0000] {logging_mixin.py:188} WARNING -   File "/home/airflow/.local/lib/python3.12/site-packages/botocore/hooks.py", line 256, in emit
    return self._emit(event_name, kwargs)
           ^^^^^^^^^^^^^^^^^^^^^^^^^^^^^^
[2024-08-19T06:17:05.983+0000] {logging_mixin.py:188} WARNING -   File "/home/airflow/.local/lib/python3.12/site-packages/botocore/hooks.py", line 239, in _emit
    response = handler(**kwargs)
               ^^^^^^^^^^^^^^^^^
[2024-08-19T06:17:05.984+0000] {logging_mixin.py:188} WARNING -   File "/home/airflow/.local/lib/python3.12/site-packages/botocore/retryhandler.py", line 207, in __call__
    if self._checker(**checker_kwargs):
       ^^^^^^^^^^^^^^^^^^^^^^^^^^^^^^^
[2024-08-19T06:17:05.984+0000] {logging_mixin.py:188} WARNING -   File "/home/airflow/.local/lib/python3.12/site-packages/botocore/retryhandler.py", line 284, in __call__
    should_retry = self._should_retry(
                   ^^^^^^^^^^^^^^^^^^^
[2024-08-19T06:17:05.984+0000] {logging_mixin.py:188} WARNING -   File "/home/airflow/.local/lib/python3.12/site-packages/botocore/retryhandler.py", line 320, in _should_retry
    return self._checker(attempt_number, response, caught_exception)
           ^^^^^^^^^^^^^^^^^^^^^^^^^^^^^^^^^^^^^^^^^^^^^^^^^^^^^^^^^
[2024-08-19T06:17:05.985+0000] {logging_mixin.py:188} WARNING -   File "/home/airflow/.local/lib/python3.12/site-packages/botocore/retryhandler.py", line 363, in __call__
    checker_response = checker(
                       ^^^^^^^^
[2024-08-19T06:17:05.985+0000] {logging_mixin.py:188} WARNING -   File "/home/airflow/.local/lib/python3.12/site-packages/botocore/retryhandler.py", line 247, in __call__
    return self._check_caught_exception(
           ^^^^^^^^^^^^^^^^^^^^^^^^^^^^^
[2024-08-19T06:17:05.985+0000] {logging_mixin.py:188} WARNING -   File "/home/airflow/.local/lib/python3.12/site-packages/botocore/retryhandler.py", line 416, in _check_caught_exception
    raise caught_exception
[2024-08-19T06:17:05.985+0000] {logging_mixin.py:188} WARNING -   File "/home/airflow/.local/lib/python3.12/site-packages/botocore/endpoint.py", line 281, in _do_get_response
    http_response = self._send(request)
                    ^^^^^^^^^^^^^^^^^^^
[2024-08-19T06:17:05.986+0000] {logging_mixin.py:188} WARNING -   File "/home/airflow/.local/lib/python3.12/site-packages/botocore/endpoint.py", line 377, in _send
    return self.http_session.send(request)
           ^^^^^^^^^^^^^^^^^^^^^^^^^^^^^^^
[2024-08-19T06:17:05.986+0000] {logging_mixin.py:188} WARNING -   File "/home/airflow/.local/lib/python3.12/site-packages/botocore/httpsession.py", line 503, in send
    raise ConnectionClosedError(
[2024-08-19T06:17:05.986+0000] {logging_mixin.py:188} WARNING - botocore.exceptions.ConnectionClosedError: Connection was closed before we received a valid response from endpoint URL: "http://host.docker.internal:9000/covid19/datasets/deaths_dataset.csv".
[2024-08-19T06:17:05.987+0000] {logging_mixin.py:188} WARNING - 
During handling of the above exception, another exception occurred:
[2024-08-19T06:17:05.987+0000] {logging_mixin.py:188} WARNING - Traceback (most recent call last):
[2024-08-19T06:17:05.987+0000] {logging_mixin.py:188} WARNING -   File "/usr/local/lib/python3.12/logging/__init__.py", line 1160, in emit
    msg = self.format(record)
          ^^^^^^^^^^^^^^^^^^^
[2024-08-19T06:17:05.988+0000] {logging_mixin.py:188} WARNING -   File "/usr/local/lib/python3.12/logging/__init__.py", line 999, in format
    return fmt.format(record)
           ^^^^^^^^^^^^^^^^^^
[2024-08-19T06:17:05.988+0000] {logging_mixin.py:188} WARNING -   File "/usr/local/lib/python3.12/logging/__init__.py", line 703, in format
    record.message = record.getMessage()
                     ^^^^^^^^^^^^^^^^^^^
[2024-08-19T06:17:05.988+0000] {logging_mixin.py:188} WARNING -   File "/usr/local/lib/python3.12/logging/__init__.py", line 392, in getMessage
    msg = msg % self.args
          ~~~~^~~~~~~~~~~
[2024-08-19T06:17:05.989+0000] {logging_mixin.py:188} WARNING - TypeError: not all arguments converted during string formatting
[2024-08-19T06:17:05.989+0000] {logging_mixin.py:188} WARNING - Call stack:
[2024-08-19T06:17:05.991+0000] {logging_mixin.py:188} WARNING -   File "/home/airflow/.local/bin/airflow", line 8, in <module>
    sys.exit(main())
[2024-08-19T06:17:05.991+0000] {logging_mixin.py:188} WARNING -   File "/home/airflow/.local/lib/python3.12/site-packages/airflow/__main__.py", line 58, in main
    args.func(args)
[2024-08-19T06:17:05.992+0000] {logging_mixin.py:188} WARNING -   File "/home/airflow/.local/lib/python3.12/site-packages/airflow/cli/cli_config.py", line 49, in command
    return func(*args, **kwargs)
[2024-08-19T06:17:05.992+0000] {logging_mixin.py:188} WARNING -   File "/home/airflow/.local/lib/python3.12/site-packages/airflow/utils/cli.py", line 114, in wrapper
    return f(*args, **kwargs)
[2024-08-19T06:17:05.993+0000] {logging_mixin.py:188} WARNING -   File "/home/airflow/.local/lib/python3.12/site-packages/airflow/providers/celery/cli/celery_command.py", line 61, in wrapper
    providers_configuration_loaded(func)(*args, **kwargs)
[2024-08-19T06:17:05.993+0000] {logging_mixin.py:188} WARNING -   File "/home/airflow/.local/lib/python3.12/site-packages/airflow/utils/providers_configuration_loader.py", line 55, in wrapped_function
    return func(*args, **kwargs)
[2024-08-19T06:17:05.993+0000] {logging_mixin.py:188} WARNING -   File "/home/airflow/.local/lib/python3.12/site-packages/airflow/providers/celery/cli/celery_command.py", line 234, in worker
    _run_command_with_daemon_option(
[2024-08-19T06:17:05.994+0000] {logging_mixin.py:188} WARNING -   File "/home/airflow/.local/lib/python3.12/site-packages/airflow/providers/celery/cli/celery_command.py", line 47, in _run_command_with_daemon_option
    run_command_with_daemon_option(*args, **kwargs)
[2024-08-19T06:17:05.994+0000] {logging_mixin.py:188} WARNING -   File "/home/airflow/.local/lib/python3.12/site-packages/airflow/cli/commands/daemon_utils.py", line 85, in run_command_with_daemon_option
    callback()
[2024-08-19T06:17:05.994+0000] {logging_mixin.py:188} WARNING -   File "/home/airflow/.local/lib/python3.12/site-packages/airflow/providers/celery/cli/celery_command.py", line 227, in run_celery_worker
    celery_app.worker_main(options)
[2024-08-19T06:17:05.995+0000] {logging_mixin.py:188} WARNING -   File "/home/airflow/.local/lib/python3.12/site-packages/celery/app/base.py", line 391, in worker_main
    self.start(argv=argv)
[2024-08-19T06:17:05.995+0000] {logging_mixin.py:188} WARNING -   File "/home/airflow/.local/lib/python3.12/site-packages/celery/app/base.py", line 371, in start
    celery.main(args=argv, standalone_mode=False)
[2024-08-19T06:17:05.995+0000] {logging_mixin.py:188} WARNING -   File "/home/airflow/.local/lib/python3.12/site-packages/click/core.py", line 1078, in main
    rv = self.invoke(ctx)
[2024-08-19T06:17:05.995+0000] {logging_mixin.py:188} WARNING -   File "/home/airflow/.local/lib/python3.12/site-packages/click/core.py", line 1688, in invoke
    return _process_result(sub_ctx.command.invoke(sub_ctx))
[2024-08-19T06:17:05.996+0000] {logging_mixin.py:188} WARNING -   File "/home/airflow/.local/lib/python3.12/site-packages/click/core.py", line 1434, in invoke
    return ctx.invoke(self.callback, **ctx.params)
[2024-08-19T06:17:05.996+0000] {logging_mixin.py:188} WARNING -   File "/home/airflow/.local/lib/python3.12/site-packages/click/core.py", line 783, in invoke
    return __callback(*args, **kwargs)
[2024-08-19T06:17:05.996+0000] {logging_mixin.py:188} WARNING -   File "/home/airflow/.local/lib/python3.12/site-packages/click/decorators.py", line 33, in new_func
    return f(get_current_context(), *args, **kwargs)
[2024-08-19T06:17:05.996+0000] {logging_mixin.py:188} WARNING -   File "/home/airflow/.local/lib/python3.12/site-packages/celery/bin/base.py", line 135, in caller
    return f(ctx, *args, **kwargs)
[2024-08-19T06:17:05.997+0000] {logging_mixin.py:188} WARNING -   File "/home/airflow/.local/lib/python3.12/site-packages/celery/bin/worker.py", line 356, in worker
    worker.start()
[2024-08-19T06:17:05.997+0000] {logging_mixin.py:188} WARNING -   File "/home/airflow/.local/lib/python3.12/site-packages/celery/worker/worker.py", line 202, in start
    self.blueprint.start(self)
[2024-08-19T06:17:05.997+0000] {logging_mixin.py:188} WARNING -   File "/home/airflow/.local/lib/python3.12/site-packages/celery/bootsteps.py", line 116, in start
    step.start(parent)
[2024-08-19T06:17:05.997+0000] {logging_mixin.py:188} WARNING -   File "/home/airflow/.local/lib/python3.12/site-packages/celery/bootsteps.py", line 365, in start
    return self.obj.start()
[2024-08-19T06:17:05.997+0000] {logging_mixin.py:188} WARNING -   File "/home/airflow/.local/lib/python3.12/site-packages/celery/concurrency/base.py", line 130, in start
    self.on_start()
[2024-08-19T06:17:05.998+0000] {logging_mixin.py:188} WARNING -   File "/home/airflow/.local/lib/python3.12/site-packages/celery/concurrency/prefork.py", line 109, in on_start
    P = self._pool = Pool(processes=self.limit,
[2024-08-19T06:17:05.998+0000] {logging_mixin.py:188} WARNING -   File "/home/airflow/.local/lib/python3.12/site-packages/celery/concurrency/asynpool.py", line 464, in __init__
    super().__init__(processes, *args, **kwargs)
[2024-08-19T06:17:05.998+0000] {logging_mixin.py:188} WARNING -   File "/home/airflow/.local/lib/python3.12/site-packages/billiard/pool.py", line 1045, in __init__
    self._create_worker_process(i)
[2024-08-19T06:17:05.998+0000] {logging_mixin.py:188} WARNING -   File "/home/airflow/.local/lib/python3.12/site-packages/celery/concurrency/asynpool.py", line 482, in _create_worker_process
    return super()._create_worker_process(i)
[2024-08-19T06:17:05.998+0000] {logging_mixin.py:188} WARNING -   File "/home/airflow/.local/lib/python3.12/site-packages/billiard/pool.py", line 1157, in _create_worker_process
    w.start()
[2024-08-19T06:17:05.999+0000] {logging_mixin.py:188} WARNING -   File "/home/airflow/.local/lib/python3.12/site-packages/billiard/process.py", line 120, in start
    self._popen = self._Popen(self)
[2024-08-19T06:17:05.999+0000] {logging_mixin.py:188} WARNING -   File "/home/airflow/.local/lib/python3.12/site-packages/billiard/context.py", line 331, in _Popen
    return Popen(process_obj)
[2024-08-19T06:17:05.999+0000] {logging_mixin.py:188} WARNING -   File "/home/airflow/.local/lib/python3.12/site-packages/billiard/popen_fork.py", line 22, in __init__
    self._launch(process_obj)
[2024-08-19T06:17:06.000+0000] {logging_mixin.py:188} WARNING -   File "/home/airflow/.local/lib/python3.12/site-packages/billiard/popen_fork.py", line 77, in _launch
    code = process_obj._bootstrap()
[2024-08-19T06:17:06.000+0000] {logging_mixin.py:188} WARNING -   File "/home/airflow/.local/lib/python3.12/site-packages/billiard/process.py", line 323, in _bootstrap
    self.run()
[2024-08-19T06:17:06.000+0000] {logging_mixin.py:188} WARNING -   File "/home/airflow/.local/lib/python3.12/site-packages/billiard/process.py", line 110, in run
    self._target(*self._args, **self._kwargs)
[2024-08-19T06:17:06.001+0000] {logging_mixin.py:188} WARNING -   File "/home/airflow/.local/lib/python3.12/site-packages/billiard/pool.py", line 291, in __call__
    sys.exit(self.workloop(pid=pid))
[2024-08-19T06:17:06.001+0000] {logging_mixin.py:188} WARNING -   File "/home/airflow/.local/lib/python3.12/site-packages/billiard/pool.py", line 361, in workloop
    result = (True, prepare_result(fun(*args, **kwargs)))
[2024-08-19T06:17:06.001+0000] {logging_mixin.py:188} WARNING -   File "/home/airflow/.local/lib/python3.12/site-packages/celery/app/trace.py", line 651, in fast_trace_task
    R, I, T, Rstr = tasks[task].__trace__(
[2024-08-19T06:17:06.001+0000] {logging_mixin.py:188} WARNING -   File "/home/airflow/.local/lib/python3.12/site-packages/celery/app/trace.py", line 453, in trace_task
    R = retval = fun(*args, **kwargs)
[2024-08-19T06:17:06.001+0000] {logging_mixin.py:188} WARNING -   File "/home/airflow/.local/lib/python3.12/site-packages/celery/app/trace.py", line 736, in __protected_call__
    return self.run(*args, **kwargs)
[2024-08-19T06:17:06.003+0000] {logging_mixin.py:188} WARNING -   File "/home/airflow/.local/lib/python3.12/site-packages/airflow/providers/celery/executors/celery_executor_utils.py", line 136, in execute_command
    _execute_in_fork(command_to_exec, celery_task_id)
[2024-08-19T06:17:06.003+0000] {logging_mixin.py:188} WARNING -   File "/home/airflow/.local/lib/python3.12/site-packages/airflow/providers/celery/executors/celery_executor_utils.py", line 172, in _execute_in_fork
    args.func(args)
[2024-08-19T06:17:06.004+0000] {logging_mixin.py:188} WARNING -   File "/home/airflow/.local/lib/python3.12/site-packages/airflow/cli/cli_config.py", line 49, in command
    return func(*args, **kwargs)
[2024-08-19T06:17:06.004+0000] {logging_mixin.py:188} WARNING -   File "/home/airflow/.local/lib/python3.12/site-packages/airflow/utils/cli.py", line 114, in wrapper
    return f(*args, **kwargs)
[2024-08-19T06:17:06.004+0000] {logging_mixin.py:188} WARNING -   File "/home/airflow/.local/lib/python3.12/site-packages/airflow/cli/commands/task_command.py", line 441, in task_run
    task_return_code = _run_task_by_selected_method(args, _dag, ti)
[2024-08-19T06:17:06.005+0000] {logging_mixin.py:188} WARNING -   File "/home/airflow/.local/lib/python3.12/site-packages/airflow/cli/commands/task_command.py", line 219, in _run_task_by_selected_method
    return _run_task_by_local_task_job(args, ti)
[2024-08-19T06:17:06.005+0000] {logging_mixin.py:188} WARNING -   File "/home/airflow/.local/lib/python3.12/site-packages/airflow/cli/commands/task_command.py", line 281, in _run_task_by_local_task_job
    ret = run_job(job=job_runner.job, execute_callable=job_runner._execute)
[2024-08-19T06:17:06.005+0000] {logging_mixin.py:188} WARNING -   File "/home/airflow/.local/lib/python3.12/site-packages/airflow/utils/session.py", line 79, in wrapper
    return func(*args, session=session, **kwargs)
[2024-08-19T06:17:06.006+0000] {logging_mixin.py:188} WARNING -   File "/home/airflow/.local/lib/python3.12/site-packages/airflow/jobs/job.py", line 402, in run_job
    return execute_job(job, execute_callable=execute_callable)
[2024-08-19T06:17:06.006+0000] {logging_mixin.py:188} WARNING -   File "/home/airflow/.local/lib/python3.12/site-packages/airflow/jobs/job.py", line 431, in execute_job
    ret = execute_callable()
[2024-08-19T06:17:06.006+0000] {logging_mixin.py:188} WARNING -   File "/home/airflow/.local/lib/python3.12/site-packages/airflow/jobs/local_task_job_runner.py", line 168, in _execute
    self.task_runner.start()
[2024-08-19T06:17:06.007+0000] {logging_mixin.py:188} WARNING -   File "/home/airflow/.local/lib/python3.12/site-packages/airflow/task/task_runner/standard_task_runner.py", line 51, in start
    self.process = self._start_by_fork()
[2024-08-19T06:17:06.007+0000] {logging_mixin.py:188} WARNING -   File "/home/airflow/.local/lib/python3.12/site-packages/airflow/task/task_runner/standard_task_runner.py", line 103, in _start_by_fork
    ret = args.func(args, dag=self.dag)
[2024-08-19T06:17:06.007+0000] {logging_mixin.py:188} WARNING -   File "/home/airflow/.local/lib/python3.12/site-packages/airflow/cli/cli_config.py", line 49, in command
    return func(*args, **kwargs)
[2024-08-19T06:17:06.008+0000] {logging_mixin.py:188} WARNING -   File "/home/airflow/.local/lib/python3.12/site-packages/airflow/utils/cli.py", line 114, in wrapper
    return f(*args, **kwargs)
[2024-08-19T06:17:06.008+0000] {logging_mixin.py:188} WARNING -   File "/home/airflow/.local/lib/python3.12/site-packages/airflow/cli/commands/task_command.py", line 441, in task_run
    task_return_code = _run_task_by_selected_method(args, _dag, ti)
[2024-08-19T06:17:06.009+0000] {logging_mixin.py:188} WARNING -   File "/home/airflow/.local/lib/python3.12/site-packages/airflow/cli/commands/task_command.py", line 221, in _run_task_by_selected_method
    return _run_raw_task(args, ti)
[2024-08-19T06:17:06.009+0000] {logging_mixin.py:188} WARNING -   File "/home/airflow/.local/lib/python3.12/site-packages/airflow/cli/commands/task_command.py", line 300, in _run_raw_task
    return ti._run_raw_task(
[2024-08-19T06:17:06.009+0000] {logging_mixin.py:188} WARNING -   File "/home/airflow/.local/lib/python3.12/site-packages/airflow/utils/session.py", line 79, in wrapper
    return func(*args, session=session, **kwargs)
[2024-08-19T06:17:06.009+0000] {logging_mixin.py:188} WARNING -   File "/home/airflow/.local/lib/python3.12/site-packages/airflow/models/taskinstance.py", line 2479, in _run_raw_task
    self._execute_task_with_callbacks(context, test_mode, session=session)
[2024-08-19T06:17:06.010+0000] {logging_mixin.py:188} WARNING -   File "/home/airflow/.local/lib/python3.12/site-packages/airflow/models/taskinstance.py", line 2676, in _execute_task_with_callbacks
    result = self._execute_task(context, task_orig)
[2024-08-19T06:17:06.010+0000] {logging_mixin.py:188} WARNING -   File "/home/airflow/.local/lib/python3.12/site-packages/airflow/models/taskinstance.py", line 2701, in _execute_task
    return _execute_task(self, context, task_orig)
[2024-08-19T06:17:06.010+0000] {logging_mixin.py:188} WARNING -   File "/home/airflow/.local/lib/python3.12/site-packages/airflow/models/taskinstance.py", line 465, in _execute_task
    result = _execute_callable(context=context, **execute_callable_kwargs)
[2024-08-19T06:17:06.010+0000] {logging_mixin.py:188} WARNING -   File "/home/airflow/.local/lib/python3.12/site-packages/airflow/models/taskinstance.py", line 432, in _execute_callable
    return execute_callable(context=context, **execute_callable_kwargs)
[2024-08-19T06:17:06.010+0000] {logging_mixin.py:188} WARNING -   File "/home/airflow/.local/lib/python3.12/site-packages/airflow/models/baseoperator.py", line 400, in wrapper
    return func(self, *args, **kwargs)
[2024-08-19T06:17:06.011+0000] {logging_mixin.py:188} WARNING -   File "/home/airflow/.local/lib/python3.12/site-packages/airflow/operators/python.py", line 235, in execute
    return_value = self.execute_callable()
[2024-08-19T06:17:06.011+0000] {logging_mixin.py:188} WARNING -   File "/home/airflow/.local/lib/python3.12/site-packages/airflow/operators/python.py", line 252, in execute_callable
    return self.python_callable(*self.op_args, **self.op_kwargs)
[2024-08-19T06:17:06.011+0000] {logging_mixin.py:188} WARNING -   File "/opt/airflow/dags/tasks/save_data_to_s3.py", line 18, in save_data_to_s3
    logging.error("Ошибка при добавлении файла в S3 bucket: ", e)
[2024-08-19T06:17:06.011+0000] {logging_mixin.py:188} WARNING -   File "/usr/local/lib/python3.12/logging/__init__.py", line 2183, in error
    root.error(msg, *args, **kwargs)
[2024-08-19T06:17:06.011+0000] {logging_mixin.py:188} WARNING -   File "/usr/local/lib/python3.12/logging/__init__.py", line 1568, in error
    self._log(ERROR, msg, args, **kwargs)
[2024-08-19T06:17:06.012+0000] {logging_mixin.py:188} WARNING -   File "/usr/local/lib/python3.12/logging/__init__.py", line 1684, in _log
    self.handle(record)
[2024-08-19T06:17:06.012+0000] {logging_mixin.py:188} WARNING -   File "/usr/local/lib/python3.12/logging/__init__.py", line 1700, in handle
    self.callHandlers(record)
[2024-08-19T06:17:06.012+0000] {logging_mixin.py:188} WARNING -   File "/usr/local/lib/python3.12/logging/__init__.py", line 1762, in callHandlers
    hdlr.handle(record)
[2024-08-19T06:17:06.012+0000] {logging_mixin.py:188} WARNING -   File "/usr/local/lib/python3.12/logging/__init__.py", line 1028, in handle
    self.emit(record)
[2024-08-19T06:17:06.012+0000] {logging_mixin.py:188} WARNING -   File "/home/airflow/.local/lib/python3.12/site-packages/airflow/utils/log/file_task_handler.py", line 248, in emit
    self.handler.emit(record)
[2024-08-19T06:17:06.013+0000] {logging_mixin.py:188} WARNING - Message: 'Ошибка при добавлении файла в S3 bucket: '
Arguments: (ConnectionClosedError('Connection was closed before we received a valid response from endpoint URL: "http://host.docker.internal:9000/covid19/datasets/deaths_dataset.csv".'),)
[2024-08-19T06:17:06.013+0000] {python.py:237} INFO - Done. Returned value was: None
[2024-08-19T06:17:06.013+0000] {taskinstance.py:441} INFO - ::group::Post task execution logs
[2024-08-19T06:17:06.020+0000] {taskinstance.py:1206} INFO - Marking task as SUCCESS. dag_id=predict_values_TS_38, task_id=get_deaths_dataset.save_data_to_s3, run_id=scheduled__2024-08-11T00:00:00+00:00, execution_date=20240811T000000, start_date=20240819T061701, end_date=20240819T061706
[2024-08-19T06:17:06.068+0000] {local_task_job_runner.py:240} INFO - Task exited with return code 0
[2024-08-19T06:17:06.075+0000] {warnings.py:110} WARNING - /home/airflow/.local/lib/python3.12/site-packages/airflow/models/baseoperator.py:1296: AirflowProviderDeprecationWarning: Call to deprecated class PostgresOperator. (Please use `airflow.providers.common.sql.operators.sql.SQLExecuteQueryOperator`.Also, you can provide `hook_params={'schema': <database>}`.)
  result = cls.__new__(cls)

[2024-08-19T06:17:06.088+0000] {taskinstance.py:3498} INFO - 2 downstream tasks scheduled from follow-on schedule check
[2024-08-19T06:17:06.092+0000] {local_task_job_runner.py:222} INFO - ::endgroup::
