[2024-08-16T05:05:28.533+0000] {local_task_job_runner.py:120} INFO - ::group::Pre task execution logs
[2024-08-16T05:05:28.546+0000] {taskinstance.py:2076} INFO - Dependencies all met for dep_context=non-requeueable deps ti=<TaskInstance: predict_values_TS_2.get_datasets_from_google scheduled__2024-08-04T00:00:00+00:00 [queued]>
[2024-08-16T05:05:28.551+0000] {taskinstance.py:2076} INFO - Dependencies all met for dep_context=requeueable deps ti=<TaskInstance: predict_values_TS_2.get_datasets_from_google scheduled__2024-08-04T00:00:00+00:00 [queued]>
[2024-08-16T05:05:28.552+0000] {taskinstance.py:2306} INFO - Starting attempt 1 of 2
[2024-08-16T05:05:28.561+0000] {taskinstance.py:2330} INFO - Executing <Task(PythonOperator): get_datasets_from_google> on 2024-08-04 00:00:00+00:00
[2024-08-16T05:05:28.566+0000] {warnings.py:110} WARNING - /home/airflow/.local/lib/python3.12/site-packages/airflow/task/task_runner/standard_task_runner.py:61: DeprecationWarning: This process (pid=287) is multi-threaded, use of fork() may lead to deadlocks in the child.
  pid = os.fork()

[2024-08-16T05:05:28.566+0000] {standard_task_runner.py:90} INFO - Running: ['airflow', 'tasks', 'run', 'predict_values_TS_2', 'get_datasets_from_google', 'scheduled__2024-08-04T00:00:00+00:00', '--job-id', '4', '--raw', '--subdir', 'DAGS_FOLDER/etl.py', '--cfg-path', '/tmp/tmp84mb4pbz']
[2024-08-16T05:05:28.568+0000] {standard_task_runner.py:63} INFO - Started process 308 to run task
[2024-08-16T05:05:28.568+0000] {standard_task_runner.py:91} INFO - Job 4: Subtask get_datasets_from_google
[2024-08-16T05:05:28.607+0000] {task_command.py:426} INFO - Running <TaskInstance: predict_values_TS_2.get_datasets_from_google scheduled__2024-08-04T00:00:00+00:00 [running]> on host 67cef99b955e
[2024-08-16T05:05:28.656+0000] {taskinstance.py:2648} INFO - Exporting env vars: AIRFLOW_CTX_DAG_OWNER='Ruslan Solarev' AIRFLOW_CTX_DAG_ID='predict_values_TS_2' AIRFLOW_CTX_TASK_ID='get_datasets_from_google' AIRFLOW_CTX_EXECUTION_DATE='2024-08-04T00:00:00+00:00' AIRFLOW_CTX_TRY_NUMBER='1' AIRFLOW_CTX_DAG_RUN_ID='scheduled__2024-08-04T00:00:00+00:00'
[2024-08-16T05:05:28.657+0000] {taskinstance.py:430} INFO - ::endgroup::
[2024-08-16T05:05:36.680+0000] {taskinstance.py:441} INFO - ::group::Post task execution logs
[2024-08-16T05:05:36.680+0000] {taskinstance.py:2905} ERROR - Task failed with exception
Traceback (most recent call last):
  File "/home/airflow/.local/lib/python3.12/site-packages/pandas/compat/_optional.py", line 132, in import_optional_dependency
    module = importlib.import_module(name)
             ^^^^^^^^^^^^^^^^^^^^^^^^^^^^^
  File "/usr/local/lib/python3.12/importlib/__init__.py", line 90, in import_module
    return _bootstrap._gcd_import(name[level:], package, level)
           ^^^^^^^^^^^^^^^^^^^^^^^^^^^^^^^^^^^^^^^^^^^^^^^^^^^^
  File "<frozen importlib._bootstrap>", line 1387, in _gcd_import
  File "<frozen importlib._bootstrap>", line 1360, in _find_and_load
  File "<frozen importlib._bootstrap>", line 1324, in _find_and_load_unlocked
ModuleNotFoundError: No module named 'openpyxl'

During handling of the above exception, another exception occurred:

Traceback (most recent call last):
  File "/home/airflow/.local/lib/python3.12/site-packages/airflow/models/taskinstance.py", line 465, in _execute_task
    result = _execute_callable(context=context, **execute_callable_kwargs)
             ^^^^^^^^^^^^^^^^^^^^^^^^^^^^^^^^^^^^^^^^^^^^^^^^^^^^^^^^^^^^^
  File "/home/airflow/.local/lib/python3.12/site-packages/airflow/models/taskinstance.py", line 432, in _execute_callable
    return execute_callable(context=context, **execute_callable_kwargs)
           ^^^^^^^^^^^^^^^^^^^^^^^^^^^^^^^^^^^^^^^^^^^^^^^^^^^^^^^^^^^^
  File "/home/airflow/.local/lib/python3.12/site-packages/airflow/models/baseoperator.py", line 400, in wrapper
    return func(self, *args, **kwargs)
           ^^^^^^^^^^^^^^^^^^^^^^^^^^^
  File "/home/airflow/.local/lib/python3.12/site-packages/airflow/operators/python.py", line 235, in execute
    return_value = self.execute_callable()
                   ^^^^^^^^^^^^^^^^^^^^^^^
  File "/home/airflow/.local/lib/python3.12/site-packages/airflow/operators/python.py", line 252, in execute_callable
    return self.python_callable(*self.op_args, **self.op_kwargs)
           ^^^^^^^^^^^^^^^^^^^^^^^^^^^^^^^^^^^^^^^^^^^^^^^^^^^^^
  File "/opt/airflow/dags/tasks_2/get_data.py", line 21, in get_data
    data = pd.read_excel(path)
           ^^^^^^^^^^^^^^^^^^^
  File "/home/airflow/.local/lib/python3.12/site-packages/pandas/io/excel/_base.py", line 504, in read_excel
    io = ExcelFile(
         ^^^^^^^^^^
  File "/home/airflow/.local/lib/python3.12/site-packages/pandas/io/excel/_base.py", line 1580, in __init__
    self._reader = self._engines[engine](
                   ^^^^^^^^^^^^^^^^^^^^^^
  File "/home/airflow/.local/lib/python3.12/site-packages/pandas/io/excel/_openpyxl.py", line 552, in __init__
    import_optional_dependency("openpyxl")
  File "/home/airflow/.local/lib/python3.12/site-packages/pandas/compat/_optional.py", line 135, in import_optional_dependency
    raise ImportError(msg)
ImportError: Missing optional dependency 'openpyxl'.  Use pip or conda to install openpyxl.
[2024-08-16T05:05:36.688+0000] {taskinstance.py:1206} INFO - Marking task as UP_FOR_RETRY. dag_id=predict_values_TS_2, task_id=get_datasets_from_google, run_id=scheduled__2024-08-04T00:00:00+00:00, execution_date=20240804T000000, start_date=20240816T050528, end_date=20240816T050536
[2024-08-16T05:05:36.697+0000] {standard_task_runner.py:110} ERROR - Failed to execute job 4 for task get_datasets_from_google (Missing optional dependency 'openpyxl'.  Use pip or conda to install openpyxl.; 308)
[2024-08-16T05:05:36.720+0000] {local_task_job_runner.py:240} INFO - Task exited with return code 1
[2024-08-16T05:05:36.729+0000] {taskinstance.py:3498} INFO - 0 downstream tasks scheduled from follow-on schedule check
[2024-08-16T05:05:36.731+0000] {local_task_job_runner.py:222} INFO - ::endgroup::
